[2024-06-28T18:32:39.134+0000] {local_task_job_runner.py:120} INFO - ::group::Pre task execution logs
[2024-06-28T18:32:39.154+0000] {taskinstance.py:2076} INFO - Dependencies all met for dep_context=non-requeueable deps ti=<TaskInstance: NYC_Taxi_pipeline.data_delivery manual__2024-06-28T18:32:27.634685+00:00 [queued]>
[2024-06-28T18:32:39.165+0000] {taskinstance.py:2076} INFO - Dependencies all met for dep_context=requeueable deps ti=<TaskInstance: NYC_Taxi_pipeline.data_delivery manual__2024-06-28T18:32:27.634685+00:00 [queued]>
[2024-06-28T18:32:39.165+0000] {taskinstance.py:2306} INFO - Starting attempt 1 of 1
[2024-06-28T18:32:39.178+0000] {taskinstance.py:2330} INFO - Executing <Task(PythonOperator): data_delivery> on 2024-06-28 18:32:27.634685+00:00
[2024-06-28T18:32:39.185+0000] {standard_task_runner.py:63} INFO - Started process 248 to run task
[2024-06-28T18:32:39.188+0000] {standard_task_runner.py:90} INFO - Running: ['***', 'tasks', 'run', 'NYC_Taxi_pipeline', 'data_delivery', 'manual__2024-06-28T18:32:27.634685+00:00', '--job-id', '92', '--raw', '--subdir', 'DAGS_FOLDER/NYC_Taxi_pipeline.py', '--cfg-path', '/tmp/tmpjf8b2sdh']
[2024-06-28T18:32:39.191+0000] {standard_task_runner.py:91} INFO - Job 92: Subtask data_delivery
[2024-06-28T18:32:39.236+0000] {task_command.py:426} INFO - Running <TaskInstance: NYC_Taxi_pipeline.data_delivery manual__2024-06-28T18:32:27.634685+00:00 [running]> on host 79a59ce16f65
[2024-06-28T18:32:39.480+0000] {taskinstance.py:2648} INFO - Exporting env vars: AIRFLOW_CTX_DAG_OWNER='Mahmoud' AIRFLOW_CTX_DAG_ID='NYC_Taxi_pipeline' AIRFLOW_CTX_TASK_ID='data_delivery' AIRFLOW_CTX_EXECUTION_DATE='2024-06-28T18:32:27.634685+00:00' AIRFLOW_CTX_TRY_NUMBER='1' AIRFLOW_CTX_DAG_RUN_ID='manual__2024-06-28T18:32:27.634685+00:00'
[2024-06-28T18:32:39.481+0000] {taskinstance.py:430} INFO - ::endgroup::
[2024-06-28T18:32:39.491+0000] {NYC_Taxi_pipeline.py:54} INFO - data_delivery started
[2024-06-28T18:32:39.491+0000] {Load_Data.py:20} INFO - Loading location Dimension ...
[2024-06-28T18:32:39.500+0000] {db_utils.py:21} INFO - Connected to PostgreSQL database successfully
[2024-06-28T18:32:39.503+0000] {Load_Data.py:37} INFO - Existing records columns: ['locationid', 'borough', 'zone', 'service_zone', 'start_date', 'end_date', 'active_flag', 'version']
[2024-06-28T18:32:39.505+0000] {Load_Data.py:91} INFO - Error loading location dimension: 'LocationID'
[2024-06-28T18:32:39.505+0000] {Load_Data.py:95} INFO - loading DimRate Dimension ...
[2024-06-28T18:32:39.507+0000] {Table_creation.py:30} INFO - Loading data into table DimRate...
[2024-06-28T18:32:39.510+0000] {db_utils.py:21} INFO - Connected to PostgreSQL database successfully
[2024-06-28T18:32:39.516+0000] {Table_creation.py:45} INFO - Data loaded successfully into table DimRate With 6 Row
[2024-06-28T18:32:39.516+0000] {db_utils.py:30} INFO - PostgreSQL connection is closed
[2024-06-28T18:32:39.516+0000] {Load_Data.py:98} INFO - DimRate_df dimension loaded successfully
[2024-06-28T18:32:39.516+0000] {Load_Data.py:113} INFO - loading payment dimension....
[2024-06-28T18:32:39.518+0000] {Table_creation.py:30} INFO - Loading data into table DimPayment...
[2024-06-28T18:32:39.522+0000] {db_utils.py:21} INFO - Connected to PostgreSQL database successfully
[2024-06-28T18:32:39.529+0000] {Table_creation.py:45} INFO - Data loaded successfully into table DimPayment With 6 Row
[2024-06-28T18:32:39.529+0000] {db_utils.py:30} INFO - PostgreSQL connection is closed
[2024-06-28T18:32:39.530+0000] {Load_Data.py:116} INFO - payment_df dimension loaded successfully
[2024-06-28T18:32:39.530+0000] {Load_Data.py:11} INFO - loading Dimvendor Dimension ...
[2024-06-28T18:32:39.533+0000] {Table_creation.py:30} INFO - Loading data into table DimRate...
[2024-06-28T18:32:39.536+0000] {db_utils.py:21} INFO - Connected to PostgreSQL database successfully
[2024-06-28T18:32:39.541+0000] {Load_Data.py:16} INFO - Error loading Dimvedor_df dimension: column "vendor_id" of relation "dimrate" does not exist
LINE 1: INSERT INTO DimRate (vendor_id,  vendor_name) VALUES (1, 'Cr...
                             ^

[2024-06-28T18:32:39.541+0000] {Load_Data.py:104} INFO - loading trip_type dimension....
[2024-06-28T18:32:39.544+0000] {Table_creation.py:30} INFO - Loading data into table DimTrip_type...
[2024-06-28T18:32:39.547+0000] {db_utils.py:21} INFO - Connected to PostgreSQL database successfully
[2024-06-28T18:32:39.553+0000] {Table_creation.py:45} INFO - Data loaded successfully into table DimTrip_type With 2 Row
[2024-06-28T18:32:39.554+0000] {db_utils.py:30} INFO - PostgreSQL connection is closed
[2024-06-28T18:32:39.554+0000] {Load_Data.py:107} INFO - trip_df dimension loaded successfully
[2024-06-28T18:32:39.555+0000] {Load_Data.py:122} INFO - loading fact table ....
[2024-06-28T18:32:43.279+0000] {Table_creation.py:30} INFO - Loading data into table Fact_Trip...
[2024-06-28T18:32:43.283+0000] {db_utils.py:21} INFO - Connected to PostgreSQL database successfully
[2024-06-28T18:34:15.080+0000] {local_task_job_runner.py:310} WARNING - State of this instance has been externally set to failed. Terminating instance.
[2024-06-28T18:34:15.082+0000] {local_task_job_runner.py:222} INFO - ::endgroup::
[2024-06-28T18:34:15.084+0000] {process_utils.py:132} INFO - Sending 15 to group 248. PIDs of all processes in the group: [248]
[2024-06-28T18:34:15.085+0000] {process_utils.py:87} INFO - Sending the signal 15 to group 248
[2024-06-28T18:34:15.085+0000] {taskinstance.py:2611} ERROR - Received SIGTERM. Terminating subprocesses.
[2024-06-28T18:34:15.090+0000] {taskinstance.py:441} INFO - ::group::Post task execution logs
[2024-06-28T18:34:15.257+0000] {process_utils.py:80} INFO - Process psutil.Process(pid=248, status='terminated', exitcode=0, started='18:32:38') (248) terminated with exit code 0
