[2024-06-28T21:35:27.298+0000] {local_task_job_runner.py:120} INFO - ::group::Pre task execution logs
[2024-06-28T21:35:27.326+0000] {taskinstance.py:2076} INFO - Dependencies all met for dep_context=non-requeueable deps ti=<TaskInstance: NYC_Taxi_pipeline.data_delivery manual__2024-06-28T21:35:23.413848+00:00 [queued]>
[2024-06-28T21:35:27.337+0000] {taskinstance.py:2076} INFO - Dependencies all met for dep_context=requeueable deps ti=<TaskInstance: NYC_Taxi_pipeline.data_delivery manual__2024-06-28T21:35:23.413848+00:00 [queued]>
[2024-06-28T21:35:27.338+0000] {taskinstance.py:2306} INFO - Starting attempt 1 of 1
[2024-06-28T21:35:27.352+0000] {taskinstance.py:2330} INFO - Executing <Task(PythonOperator): data_delivery> on 2024-06-28 21:35:23.413848+00:00
[2024-06-28T21:35:27.362+0000] {standard_task_runner.py:63} INFO - Started process 349 to run task
[2024-06-28T21:35:27.365+0000] {standard_task_runner.py:90} INFO - Running: ['***', 'tasks', 'run', 'NYC_Taxi_pipeline', 'data_delivery', 'manual__2024-06-28T21:35:23.413848+00:00', '--job-id', '125', '--raw', '--subdir', 'DAGS_FOLDER/NYC_Taxi_pipeline.py', '--cfg-path', '/tmp/tmpiujqkmyn']
[2024-06-28T21:35:27.368+0000] {standard_task_runner.py:91} INFO - Job 125: Subtask data_delivery
[2024-06-28T21:35:27.419+0000] {task_command.py:426} INFO - Running <TaskInstance: NYC_Taxi_pipeline.data_delivery manual__2024-06-28T21:35:23.413848+00:00 [running]> on host 79a59ce16f65
[2024-06-28T21:35:27.709+0000] {taskinstance.py:2648} INFO - Exporting env vars: AIRFLOW_CTX_DAG_OWNER='Mahmoud' AIRFLOW_CTX_DAG_ID='NYC_Taxi_pipeline' AIRFLOW_CTX_TASK_ID='data_delivery' AIRFLOW_CTX_EXECUTION_DATE='2024-06-28T21:35:23.413848+00:00' AIRFLOW_CTX_TRY_NUMBER='1' AIRFLOW_CTX_DAG_RUN_ID='manual__2024-06-28T21:35:23.413848+00:00'
[2024-06-28T21:35:27.710+0000] {taskinstance.py:430} INFO - ::endgroup::
[2024-06-28T21:35:27.724+0000] {NYC_Taxi_pipeline.py:54} INFO - data_delivery started
[2024-06-28T21:35:27.724+0000] {Load_Data.py:21} INFO - Loading location Dimension ...
[2024-06-28T21:35:27.734+0000] {db_utils.py:21} INFO - Connected to PostgreSQL database successfully
[2024-06-28T21:35:27.738+0000] {Load_Data.py:36} INFO - Existing records columns: ['locationid', 'borough', 'zone', 'service_zone', 'start_date', 'end_date', 'active_flag', 'version']
[2024-06-28T21:35:28.013+0000] {Load_Data.py:91} INFO - Error loading location dimension: [Errno 21] Is a directory: './datalake'
[2024-06-28T21:35:28.014+0000] {Load_Data.py:96} INFO - loading DimRate Dimension ...
[2024-06-28T21:35:28.017+0000] {Table_creation.py:30} INFO - Loading data into table DimRate...
[2024-06-28T21:35:28.021+0000] {db_utils.py:21} INFO - Connected to PostgreSQL database successfully
[2024-06-28T21:35:28.031+0000] {Table_creation.py:45} INFO - Data loaded successfully into table DimRate With 6 Row
[2024-06-28T21:35:28.032+0000] {db_utils.py:30} INFO - PostgreSQL connection is closed
[2024-06-28T21:35:28.032+0000] {Load_Data.py:99} INFO - DimRate_df dimension loaded successfully
[2024-06-28T21:35:28.032+0000] {Load_Data.py:114} INFO - loading payment dimension....
[2024-06-28T21:35:28.035+0000] {Table_creation.py:30} INFO - Loading data into table DimPayment...
[2024-06-28T21:35:28.039+0000] {db_utils.py:21} INFO - Connected to PostgreSQL database successfully
[2024-06-28T21:35:28.047+0000] {Table_creation.py:45} INFO - Data loaded successfully into table DimPayment With 6 Row
[2024-06-28T21:35:28.048+0000] {db_utils.py:30} INFO - PostgreSQL connection is closed
[2024-06-28T21:35:28.048+0000] {Load_Data.py:117} INFO - payment_df dimension loaded successfully
[2024-06-28T21:35:28.048+0000] {Load_Data.py:11} INFO - loading Dimvendor Dimension ...
[2024-06-28T21:35:28.051+0000] {Table_creation.py:30} INFO - Loading data into table DimVendor...
[2024-06-28T21:35:28.054+0000] {db_utils.py:21} INFO - Connected to PostgreSQL database successfully
[2024-06-28T21:35:28.061+0000] {Table_creation.py:45} INFO - Data loaded successfully into table DimVendor With 2 Row
[2024-06-28T21:35:28.062+0000] {db_utils.py:30} INFO - PostgreSQL connection is closed
[2024-06-28T21:35:28.062+0000] {Load_Data.py:14} INFO - Dimvedor_df dimension loaded successfully
[2024-06-28T21:35:28.062+0000] {Load_Data.py:105} INFO - loading trip_type dimension....
[2024-06-28T21:35:28.067+0000] {Table_creation.py:30} INFO - Loading data into table DimTrip_type...
[2024-06-28T21:35:28.071+0000] {db_utils.py:21} INFO - Connected to PostgreSQL database successfully
[2024-06-28T21:35:28.079+0000] {Table_creation.py:45} INFO - Data loaded successfully into table DimTrip_type With 2 Row
[2024-06-28T21:35:28.079+0000] {db_utils.py:30} INFO - PostgreSQL connection is closed
[2024-06-28T21:35:28.080+0000] {Load_Data.py:108} INFO - trip_df dimension loaded successfully
[2024-06-28T21:35:28.080+0000] {Load_Data.py:123} INFO - loading fact table ....
[2024-06-28T21:35:31.778+0000] {Table_creation.py:30} INFO - Loading data into table Fact_Trip...
[2024-06-28T21:35:31.781+0000] {db_utils.py:21} INFO - Connected to PostgreSQL database successfully
[2024-06-28T21:36:12.755+0000] {local_task_job_runner.py:310} WARNING - State of this instance has been externally set to failed. Terminating instance.
[2024-06-28T21:36:12.757+0000] {local_task_job_runner.py:222} INFO - ::endgroup::
[2024-06-28T21:36:12.758+0000] {process_utils.py:132} INFO - Sending 15 to group 349. PIDs of all processes in the group: [349]
[2024-06-28T21:36:12.759+0000] {process_utils.py:87} INFO - Sending the signal 15 to group 349
[2024-06-28T21:36:12.759+0000] {taskinstance.py:2611} ERROR - Received SIGTERM. Terminating subprocesses.
[2024-06-28T21:36:12.760+0000] {taskinstance.py:441} INFO - ::group::Post task execution logs
[2024-06-28T21:36:13.011+0000] {process_utils.py:80} INFO - Process psutil.Process(pid=349, status='terminated', exitcode=0, started='21:35:26') (349) terminated with exit code 0
