[2024-06-14T08:15:02.254+0000] {local_task_job_runner.py:120} INFO - ::group::Pre task execution logs
[2024-06-14T08:15:02.276+0000] {taskinstance.py:2076} INFO - Dependencies all met for dep_context=non-requeueable deps ti=<TaskInstance: NYC_Taxi_pipeline.data_delivery scheduled__2024-06-13T00:00:00+00:00 [queued]>
[2024-06-14T08:15:02.283+0000] {taskinstance.py:2076} INFO - Dependencies all met for dep_context=requeueable deps ti=<TaskInstance: NYC_Taxi_pipeline.data_delivery scheduled__2024-06-13T00:00:00+00:00 [queued]>
[2024-06-14T08:15:02.283+0000] {taskinstance.py:2306} INFO - Starting attempt 1 of 1
[2024-06-14T08:15:02.294+0000] {taskinstance.py:2330} INFO - Executing <Task(PythonOperator): data_delivery> on 2024-06-13 00:00:00+00:00
[2024-06-14T08:15:02.301+0000] {standard_task_runner.py:63} INFO - Started process 57 to run task
[2024-06-14T08:15:02.304+0000] {standard_task_runner.py:90} INFO - Running: ['***', 'tasks', 'run', 'NYC_Taxi_pipeline', 'data_delivery', 'scheduled__2024-06-13T00:00:00+00:00', '--job-id', '7', '--raw', '--subdir', 'DAGS_FOLDER/NYC_Taxi_pipeline.py', '--cfg-path', '/tmp/tmpt8b0z6he']
[2024-06-14T08:15:02.306+0000] {standard_task_runner.py:91} INFO - Job 7: Subtask data_delivery
[2024-06-14T08:15:02.348+0000] {task_command.py:426} INFO - Running <TaskInstance: NYC_Taxi_pipeline.data_delivery scheduled__2024-06-13T00:00:00+00:00 [running]> on host 762c91fd0326
[2024-06-14T08:15:02.584+0000] {taskinstance.py:2648} INFO - Exporting env vars: AIRFLOW_CTX_DAG_OWNER='Mahmoud' AIRFLOW_CTX_DAG_ID='NYC_Taxi_pipeline' AIRFLOW_CTX_TASK_ID='data_delivery' AIRFLOW_CTX_EXECUTION_DATE='2024-06-13T00:00:00+00:00' AIRFLOW_CTX_TRY_NUMBER='1' AIRFLOW_CTX_DAG_RUN_ID='scheduled__2024-06-13T00:00:00+00:00'
[2024-06-14T08:15:02.585+0000] {taskinstance.py:430} INFO - ::endgroup::
[2024-06-14T08:15:02.598+0000] {NYC_Taxi_pipeline.py:54} INFO - data_delivery started
[2024-06-14T08:15:02.598+0000] {Load_Data.py:19} INFO - loading location Dimension ...
[2024-06-14T08:15:02.602+0000] {Table_creation.py:30} INFO - Loading data into table DimVendor...
[2024-06-14T08:15:02.605+0000] {db_utils.py:24} ERROR - Error while connecting to PostgreSQL: connection to server at "172.20.0.3", port 5432 failed: FATAL:  database "NYC_Taxi" does not exist

[2024-06-14T08:15:02.606+0000] {Table_creation.py:48} ERROR - Failed to connect to the database and load data into table DimVendor
[2024-06-14T08:15:02.606+0000] {Load_Data.py:22} INFO - DimLocation_df dimension loaded successfully
[2024-06-14T08:15:02.606+0000] {Load_Data.py:28} INFO - loading DimRate Dimension ...
[2024-06-14T08:15:02.608+0000] {Table_creation.py:30} INFO - Loading data into table DimVendor...
[2024-06-14T08:15:02.610+0000] {db_utils.py:24} ERROR - Error while connecting to PostgreSQL: connection to server at "172.20.0.3", port 5432 failed: FATAL:  database "NYC_Taxi" does not exist

[2024-06-14T08:15:02.610+0000] {Table_creation.py:48} ERROR - Failed to connect to the database and load data into table DimVendor
[2024-06-14T08:15:02.611+0000] {Load_Data.py:31} INFO - DimRate_df dimension loaded successfully
[2024-06-14T08:15:02.611+0000] {Load_Data.py:46} INFO - loading payment dimension....
[2024-06-14T08:15:02.612+0000] {Table_creation.py:30} INFO - Loading data into table DimPayment...
[2024-06-14T08:15:02.614+0000] {db_utils.py:24} ERROR - Error while connecting to PostgreSQL: connection to server at "172.20.0.3", port 5432 failed: FATAL:  database "NYC_Taxi" does not exist

[2024-06-14T08:15:02.615+0000] {Table_creation.py:48} ERROR - Failed to connect to the database and load data into table DimPayment
[2024-06-14T08:15:02.615+0000] {Load_Data.py:49} INFO - payment_df dimension loaded successfully
[2024-06-14T08:15:02.615+0000] {Load_Data.py:10} INFO - loading vendor Dimension ...
[2024-06-14T08:15:02.617+0000] {Table_creation.py:30} INFO - Loading data into table DimVendor...
[2024-06-14T08:15:02.619+0000] {db_utils.py:24} ERROR - Error while connecting to PostgreSQL: connection to server at "172.20.0.3", port 5432 failed: FATAL:  database "NYC_Taxi" does not exist

[2024-06-14T08:15:02.619+0000] {Table_creation.py:48} ERROR - Failed to connect to the database and load data into table DimVendor
[2024-06-14T08:15:02.619+0000] {Load_Data.py:13} INFO - vendor_df dimension loaded successfully
[2024-06-14T08:15:02.620+0000] {Load_Data.py:37} INFO - loading trip_type dimension....
[2024-06-14T08:15:02.622+0000] {Table_creation.py:30} INFO - Loading data into table DimTrip_type...
[2024-06-14T08:15:02.624+0000] {db_utils.py:24} ERROR - Error while connecting to PostgreSQL: connection to server at "172.20.0.3", port 5432 failed: FATAL:  database "NYC_Taxi" does not exist

[2024-06-14T08:15:02.624+0000] {Table_creation.py:48} ERROR - Failed to connect to the database and load data into table DimTrip_type
[2024-06-14T08:15:02.625+0000] {Load_Data.py:40} INFO - trip_df dimension loaded successfully
[2024-06-14T08:15:02.625+0000] {NYC_Taxi_pipeline.py:60} INFO - data_delivery done
[2024-06-14T08:15:02.625+0000] {python.py:237} INFO - Done. Returned value was: None
[2024-06-14T08:15:02.625+0000] {taskinstance.py:441} INFO - ::group::Post task execution logs
[2024-06-14T08:15:02.633+0000] {taskinstance.py:1206} INFO - Marking task as SUCCESS. dag_id=NYC_Taxi_pipeline, task_id=data_delivery, run_id=scheduled__2024-06-13T00:00:00+00:00, execution_date=20240613T000000, start_date=20240614T081502, end_date=20240614T081502
[2024-06-14T08:15:02.676+0000] {local_task_job_runner.py:240} INFO - Task exited with return code 0
[2024-06-14T08:15:02.694+0000] {taskinstance.py:3498} INFO - 0 downstream tasks scheduled from follow-on schedule check
[2024-06-14T08:15:02.695+0000] {local_task_job_runner.py:222} INFO - ::endgroup::
