[2024-06-28T19:05:02.880+0000] {local_task_job_runner.py:120} INFO - ::group::Pre task execution logs
[2024-06-28T19:05:02.902+0000] {taskinstance.py:2076} INFO - Dependencies all met for dep_context=non-requeueable deps ti=<TaskInstance: NYC_Taxi_pipeline.data_delivery manual__2024-06-28T19:04:52.203815+00:00 [queued]>
[2024-06-28T19:05:02.913+0000] {taskinstance.py:2076} INFO - Dependencies all met for dep_context=requeueable deps ti=<TaskInstance: NYC_Taxi_pipeline.data_delivery manual__2024-06-28T19:04:52.203815+00:00 [queued]>
[2024-06-28T19:05:02.914+0000] {taskinstance.py:2306} INFO - Starting attempt 1 of 1
[2024-06-28T19:05:02.926+0000] {taskinstance.py:2330} INFO - Executing <Task(PythonOperator): data_delivery> on 2024-06-28 19:04:52.203815+00:00
[2024-06-28T19:05:02.934+0000] {standard_task_runner.py:63} INFO - Started process 293 to run task
[2024-06-28T19:05:02.937+0000] {standard_task_runner.py:90} INFO - Running: ['***', 'tasks', 'run', 'NYC_Taxi_pipeline', 'data_delivery', 'manual__2024-06-28T19:04:52.203815+00:00', '--job-id', '107', '--raw', '--subdir', 'DAGS_FOLDER/NYC_Taxi_pipeline.py', '--cfg-path', '/tmp/tmp87ddr4hb']
[2024-06-28T19:05:02.940+0000] {standard_task_runner.py:91} INFO - Job 107: Subtask data_delivery
[2024-06-28T19:05:02.982+0000] {task_command.py:426} INFO - Running <TaskInstance: NYC_Taxi_pipeline.data_delivery manual__2024-06-28T19:04:52.203815+00:00 [running]> on host 79a59ce16f65
[2024-06-28T19:05:03.238+0000] {taskinstance.py:2648} INFO - Exporting env vars: AIRFLOW_CTX_DAG_OWNER='Mahmoud' AIRFLOW_CTX_DAG_ID='NYC_Taxi_pipeline' AIRFLOW_CTX_TASK_ID='data_delivery' AIRFLOW_CTX_EXECUTION_DATE='2024-06-28T19:04:52.203815+00:00' AIRFLOW_CTX_TRY_NUMBER='1' AIRFLOW_CTX_DAG_RUN_ID='manual__2024-06-28T19:04:52.203815+00:00'
[2024-06-28T19:05:03.239+0000] {taskinstance.py:430} INFO - ::endgroup::
[2024-06-28T19:05:03.250+0000] {NYC_Taxi_pipeline.py:54} INFO - data_delivery started
[2024-06-28T19:05:03.250+0000] {Load_Data.py:20} INFO - Loading location Dimension ...
[2024-06-28T19:05:03.257+0000] {db_utils.py:21} INFO - Connected to PostgreSQL database successfully
[2024-06-28T19:05:43.518+0000] {Load_Data.py:90} INFO - Error loading location dimension: relation "dimlocation" does not exist
LINE 1: SELECT * FROM DimLocation WHERE active_flag = 'Y'
                      ^

[2024-06-28T19:05:43.519+0000] {Load_Data.py:95} INFO - loading DimRate Dimension ...
[2024-06-28T19:05:43.523+0000] {Table_creation.py:30} INFO - Loading data into table DimRate...
[2024-06-28T19:05:43.531+0000] {db_utils.py:21} INFO - Connected to PostgreSQL database successfully
[2024-06-28T19:05:43.540+0000] {Table_creation.py:45} INFO - Data loaded successfully into table DimRate With 6 Row
[2024-06-28T19:05:43.541+0000] {db_utils.py:30} INFO - PostgreSQL connection is closed
[2024-06-28T19:05:43.541+0000] {Load_Data.py:98} INFO - DimRate_df dimension loaded successfully
[2024-06-28T19:05:43.541+0000] {Load_Data.py:113} INFO - loading payment dimension....
[2024-06-28T19:05:43.545+0000] {Table_creation.py:30} INFO - Loading data into table DimPayment...
[2024-06-28T19:05:43.550+0000] {db_utils.py:21} INFO - Connected to PostgreSQL database successfully
[2024-06-28T19:05:43.551+0000] {Load_Data.py:118} INFO - Error loading payment dimension: relation "dimpayment" does not exist

[2024-06-28T19:05:43.552+0000] {Load_Data.py:11} INFO - loading Dimvendor Dimension ...
[2024-06-28T19:05:43.554+0000] {Table_creation.py:30} INFO - Loading data into table DimVendor...
[2024-06-28T19:05:43.559+0000] {db_utils.py:21} INFO - Connected to PostgreSQL database successfully
[2024-06-28T19:05:43.567+0000] {Table_creation.py:45} INFO - Data loaded successfully into table DimVendor With 2 Row
[2024-06-28T19:05:43.567+0000] {db_utils.py:30} INFO - PostgreSQL connection is closed
[2024-06-28T19:05:43.568+0000] {Load_Data.py:14} INFO - Dimvedor_df dimension loaded successfully
[2024-06-28T19:05:43.568+0000] {Load_Data.py:104} INFO - loading trip_type dimension....
[2024-06-28T19:05:43.570+0000] {Table_creation.py:30} INFO - Loading data into table DimTrip_type...
[2024-06-28T19:05:43.573+0000] {db_utils.py:21} INFO - Connected to PostgreSQL database successfully
[2024-06-28T19:05:43.579+0000] {Table_creation.py:45} INFO - Data loaded successfully into table DimTrip_type With 2 Row
[2024-06-28T19:05:43.579+0000] {db_utils.py:30} INFO - PostgreSQL connection is closed
[2024-06-28T19:05:43.580+0000] {Load_Data.py:107} INFO - trip_df dimension loaded successfully
[2024-06-28T19:05:43.580+0000] {Load_Data.py:122} INFO - loading fact table ....
[2024-06-28T19:05:47.797+0000] {Table_creation.py:30} INFO - Loading data into table Fact_Trip...
[2024-06-28T19:05:47.800+0000] {db_utils.py:21} INFO - Connected to PostgreSQL database successfully
[2024-06-28T19:07:19.147+0000] {local_task_job_runner.py:310} WARNING - State of this instance has been externally set to failed. Terminating instance.
[2024-06-28T19:07:19.148+0000] {local_task_job_runner.py:222} INFO - ::endgroup::
[2024-06-28T19:07:19.150+0000] {process_utils.py:132} INFO - Sending 15 to group 293. PIDs of all processes in the group: [293]
[2024-06-28T19:07:19.150+0000] {process_utils.py:87} INFO - Sending the signal 15 to group 293
[2024-06-28T19:07:19.150+0000] {taskinstance.py:2611} ERROR - Received SIGTERM. Terminating subprocesses.
[2024-06-28T19:07:19.156+0000] {taskinstance.py:441} INFO - ::group::Post task execution logs
[2024-06-28T19:07:19.323+0000] {process_utils.py:80} INFO - Process psutil.Process(pid=293, status='terminated', exitcode=0, started='19:05:02') (293) terminated with exit code 0
