[2024-06-28T23:01:23.549+0000] {local_task_job_runner.py:120} INFO - ::group::Pre task execution logs
[2024-06-28T23:01:23.574+0000] {taskinstance.py:2076} INFO - Dependencies all met for dep_context=non-requeueable deps ti=<TaskInstance: NYC_Taxi_pipeline.database_preparation manual__2024-06-28T23:01:22.097185+00:00 [queued]>
[2024-06-28T23:01:23.583+0000] {taskinstance.py:2076} INFO - Dependencies all met for dep_context=requeueable deps ti=<TaskInstance: NYC_Taxi_pipeline.database_preparation manual__2024-06-28T23:01:22.097185+00:00 [queued]>
[2024-06-28T23:01:23.584+0000] {taskinstance.py:2306} INFO - Starting attempt 1 of 1
[2024-06-28T23:01:23.597+0000] {taskinstance.py:2330} INFO - Executing <Task(PythonOperator): database_preparation> on 2024-06-28 23:01:22.097185+00:00
[2024-06-28T23:01:23.605+0000] {standard_task_runner.py:63} INFO - Started process 496 to run task
[2024-06-28T23:01:23.608+0000] {standard_task_runner.py:90} INFO - Running: ['***', 'tasks', 'run', 'NYC_Taxi_pipeline', 'database_preparation', 'manual__2024-06-28T23:01:22.097185+00:00', '--job-id', '174', '--raw', '--subdir', 'DAGS_FOLDER/NYC_Taxi_pipeline.py', '--cfg-path', '/tmp/tmpnb7x4l70']
[2024-06-28T23:01:23.611+0000] {standard_task_runner.py:91} INFO - Job 174: Subtask database_preparation
[2024-06-28T23:01:23.658+0000] {task_command.py:426} INFO - Running <TaskInstance: NYC_Taxi_pipeline.database_preparation manual__2024-06-28T23:01:22.097185+00:00 [running]> on host 79a59ce16f65
[2024-06-28T23:01:23.910+0000] {taskinstance.py:2648} INFO - Exporting env vars: AIRFLOW_CTX_DAG_OWNER='Mahmoud' AIRFLOW_CTX_DAG_ID='NYC_Taxi_pipeline' AIRFLOW_CTX_TASK_ID='database_preparation' AIRFLOW_CTX_EXECUTION_DATE='2024-06-28T23:01:22.097185+00:00' AIRFLOW_CTX_TRY_NUMBER='1' AIRFLOW_CTX_DAG_RUN_ID='manual__2024-06-28T23:01:22.097185+00:00'
[2024-06-28T23:01:23.911+0000] {taskinstance.py:430} INFO - ::endgroup::
[2024-06-28T23:01:23.921+0000] {NYC_Taxi_pipeline.py:37} INFO - database_preparation started
[2024-06-28T23:01:23.921+0000] {Table_creation.py:8} INFO - Create tables ......
[2024-06-28T23:01:23.925+0000] {db_utils.py:21} INFO - Connected to PostgreSQL database successfully
[2024-06-28T23:01:23.926+0000] {logging_mixin.py:188} WARNING - --- Logging error ---
[2024-06-28T23:01:23.926+0000] {logging_mixin.py:188} WARNING - Traceback (most recent call last):
[2024-06-28T23:01:23.927+0000] {logging_mixin.py:188} WARNING -   File "/opt/***/dags/NYC_Taxi_pipeline.py", line 38, in database_preparation
    creat_tables(**db_credentials)
[2024-06-28T23:01:23.927+0000] {logging_mixin.py:188} WARNING -   File "/opt/***/dags/scripts/Table_creation.py", line 21, in creat_tables
    if execute_query(connection=conn,query=query,table_name=table,params=None):
[2024-06-28T23:01:23.927+0000] {logging_mixin.py:188} WARNING - TypeError: execute_query() got an unexpected keyword argument 'params'
[2024-06-28T23:01:23.927+0000] {logging_mixin.py:188} WARNING - 
During handling of the above exception, another exception occurred:
[2024-06-28T23:01:23.927+0000] {logging_mixin.py:188} WARNING - Traceback (most recent call last):
[2024-06-28T23:01:23.927+0000] {logging_mixin.py:188} WARNING -   File "/usr/local/lib/python3.9/logging/__init__.py", line 1083, in emit
    msg = self.format(record)
[2024-06-28T23:01:23.927+0000] {logging_mixin.py:188} WARNING -   File "/usr/local/lib/python3.9/logging/__init__.py", line 927, in format
    return fmt.format(record)
[2024-06-28T23:01:23.927+0000] {logging_mixin.py:188} WARNING -   File "/usr/local/lib/python3.9/logging/__init__.py", line 663, in format
    record.message = record.getMessage()
[2024-06-28T23:01:23.928+0000] {logging_mixin.py:188} WARNING -   File "/usr/local/lib/python3.9/logging/__init__.py", line 367, in getMessage
    msg = msg % self.args
[2024-06-28T23:01:23.928+0000] {logging_mixin.py:188} WARNING - TypeError: not all arguments converted during string formatting
[2024-06-28T23:01:23.928+0000] {logging_mixin.py:188} WARNING - Call stack:
[2024-06-28T23:01:23.944+0000] {logging_mixin.py:188} WARNING -   File "/home/***/.local/bin/***", line 8, in <module>
    sys.exit(main())
[2024-06-28T23:01:23.945+0000] {logging_mixin.py:188} WARNING -   File "/home/***/.local/lib/python3.9/site-packages/***/__main__.py", line 58, in main
    args.func(args)
[2024-06-28T23:01:23.945+0000] {logging_mixin.py:188} WARNING -   File "/home/***/.local/lib/python3.9/site-packages/***/cli/cli_config.py", line 49, in command
    return func(*args, **kwargs)
[2024-06-28T23:01:23.945+0000] {logging_mixin.py:188} WARNING -   File "/home/***/.local/lib/python3.9/site-packages/***/utils/cli.py", line 114, in wrapper
    return f(*args, **kwargs)
[2024-06-28T23:01:23.945+0000] {logging_mixin.py:188} WARNING -   File "/home/***/.local/lib/python3.9/site-packages/***/utils/providers_configuration_loader.py", line 55, in wrapped_function
    return func(*args, **kwargs)
[2024-06-28T23:01:23.945+0000] {logging_mixin.py:188} WARNING -   File "/home/***/.local/lib/python3.9/site-packages/***/cli/commands/celery_command.py", line 218, in worker
    run_command_with_daemon_option(
[2024-06-28T23:01:23.946+0000] {logging_mixin.py:188} WARNING -   File "/home/***/.local/lib/python3.9/site-packages/***/cli/commands/daemon_utils.py", line 85, in run_command_with_daemon_option
    callback()
[2024-06-28T23:01:23.946+0000] {logging_mixin.py:188} WARNING -   File "/home/***/.local/lib/python3.9/site-packages/***/cli/commands/celery_command.py", line 211, in run_celery_worker
    celery_app.worker_main(options)
[2024-06-28T23:01:23.946+0000] {logging_mixin.py:188} WARNING -   File "/home/***/.local/lib/python3.9/site-packages/celery/app/base.py", line 391, in worker_main
    self.start(argv=argv)
[2024-06-28T23:01:23.946+0000] {logging_mixin.py:188} WARNING -   File "/home/***/.local/lib/python3.9/site-packages/celery/app/base.py", line 371, in start
    celery.main(args=argv, standalone_mode=False)
[2024-06-28T23:01:23.946+0000] {logging_mixin.py:188} WARNING -   File "/home/***/.local/lib/python3.9/site-packages/click/core.py", line 1055, in main
    rv = self.invoke(ctx)
[2024-06-28T23:01:23.946+0000] {logging_mixin.py:188} WARNING -   File "/home/***/.local/lib/python3.9/site-packages/click/core.py", line 1657, in invoke
    return _process_result(sub_ctx.command.invoke(sub_ctx))
[2024-06-28T23:01:23.946+0000] {logging_mixin.py:188} WARNING -   File "/home/***/.local/lib/python3.9/site-packages/click/core.py", line 1404, in invoke
    return ctx.invoke(self.callback, **ctx.params)
[2024-06-28T23:01:23.946+0000] {logging_mixin.py:188} WARNING -   File "/home/***/.local/lib/python3.9/site-packages/click/core.py", line 760, in invoke
    return __callback(*args, **kwargs)
[2024-06-28T23:01:23.947+0000] {logging_mixin.py:188} WARNING -   File "/home/***/.local/lib/python3.9/site-packages/click/decorators.py", line 26, in new_func
    return f(get_current_context(), *args, **kwargs)
[2024-06-28T23:01:23.947+0000] {logging_mixin.py:188} WARNING -   File "/home/***/.local/lib/python3.9/site-packages/celery/bin/base.py", line 135, in caller
    return f(ctx, *args, **kwargs)
[2024-06-28T23:01:23.947+0000] {logging_mixin.py:188} WARNING -   File "/home/***/.local/lib/python3.9/site-packages/celery/bin/worker.py", line 356, in worker
    worker.start()
[2024-06-28T23:01:23.947+0000] {logging_mixin.py:188} WARNING -   File "/home/***/.local/lib/python3.9/site-packages/celery/worker/worker.py", line 202, in start
    self.blueprint.start(self)
[2024-06-28T23:01:23.947+0000] {logging_mixin.py:188} WARNING -   File "/home/***/.local/lib/python3.9/site-packages/celery/bootsteps.py", line 116, in start
    step.start(parent)
[2024-06-28T23:01:23.947+0000] {logging_mixin.py:188} WARNING -   File "/home/***/.local/lib/python3.9/site-packages/celery/bootsteps.py", line 365, in start
    return self.obj.start()
[2024-06-28T23:01:23.947+0000] {logging_mixin.py:188} WARNING -   File "/home/***/.local/lib/python3.9/site-packages/celery/concurrency/base.py", line 130, in start
    self.on_start()
[2024-06-28T23:01:23.947+0000] {logging_mixin.py:188} WARNING -   File "/home/***/.local/lib/python3.9/site-packages/celery/concurrency/prefork.py", line 109, in on_start
    P = self._pool = Pool(processes=self.limit,
[2024-06-28T23:01:23.948+0000] {logging_mixin.py:188} WARNING -   File "/home/***/.local/lib/python3.9/site-packages/celery/concurrency/asynpool.py", line 464, in __init__
    super().__init__(processes, *args, **kwargs)
[2024-06-28T23:01:23.948+0000] {logging_mixin.py:188} WARNING -   File "/home/***/.local/lib/python3.9/site-packages/billiard/pool.py", line 1045, in __init__
    self._create_worker_process(i)
[2024-06-28T23:01:23.948+0000] {logging_mixin.py:188} WARNING -   File "/home/***/.local/lib/python3.9/site-packages/celery/concurrency/asynpool.py", line 482, in _create_worker_process
    return super()._create_worker_process(i)
[2024-06-28T23:01:23.948+0000] {logging_mixin.py:188} WARNING -   File "/home/***/.local/lib/python3.9/site-packages/billiard/pool.py", line 1157, in _create_worker_process
    w.start()
[2024-06-28T23:01:23.948+0000] {logging_mixin.py:188} WARNING -   File "/home/***/.local/lib/python3.9/site-packages/billiard/process.py", line 120, in start
    self._popen = self._Popen(self)
[2024-06-28T23:01:23.948+0000] {logging_mixin.py:188} WARNING -   File "/home/***/.local/lib/python3.9/site-packages/billiard/context.py", line 331, in _Popen
    return Popen(process_obj)
[2024-06-28T23:01:23.948+0000] {logging_mixin.py:188} WARNING -   File "/home/***/.local/lib/python3.9/site-packages/billiard/popen_fork.py", line 22, in __init__
    self._launch(process_obj)
[2024-06-28T23:01:23.948+0000] {logging_mixin.py:188} WARNING -   File "/home/***/.local/lib/python3.9/site-packages/billiard/popen_fork.py", line 77, in _launch
    code = process_obj._bootstrap()
[2024-06-28T23:01:23.948+0000] {logging_mixin.py:188} WARNING -   File "/home/***/.local/lib/python3.9/site-packages/billiard/process.py", line 323, in _bootstrap
    self.run()
[2024-06-28T23:01:23.949+0000] {logging_mixin.py:188} WARNING -   File "/home/***/.local/lib/python3.9/site-packages/billiard/process.py", line 110, in run
    self._target(*self._args, **self._kwargs)
[2024-06-28T23:01:23.949+0000] {logging_mixin.py:188} WARNING -   File "/home/***/.local/lib/python3.9/site-packages/billiard/pool.py", line 291, in __call__
    sys.exit(self.workloop(pid=pid))
[2024-06-28T23:01:23.949+0000] {logging_mixin.py:188} WARNING -   File "/home/***/.local/lib/python3.9/site-packages/billiard/pool.py", line 361, in workloop
    result = (True, prepare_result(fun(*args, **kwargs)))
[2024-06-28T23:01:23.949+0000] {logging_mixin.py:188} WARNING -   File "/home/***/.local/lib/python3.9/site-packages/celery/app/trace.py", line 651, in fast_trace_task
    R, I, T, Rstr = tasks[task].__trace__(
[2024-06-28T23:01:23.949+0000] {logging_mixin.py:188} WARNING -   File "/home/***/.local/lib/python3.9/site-packages/celery/app/trace.py", line 453, in trace_task
    R = retval = fun(*args, **kwargs)
[2024-06-28T23:01:23.949+0000] {logging_mixin.py:188} WARNING -   File "/home/***/.local/lib/python3.9/site-packages/celery/app/trace.py", line 736, in __protected_call__
    return self.run(*args, **kwargs)
[2024-06-28T23:01:23.949+0000] {logging_mixin.py:188} WARNING -   File "/home/***/.local/lib/python3.9/site-packages/***/providers/celery/executors/celery_executor_utils.py", line 134, in execute_command
    _execute_in_fork(command_to_exec, celery_task_id)
[2024-06-28T23:01:23.949+0000] {logging_mixin.py:188} WARNING -   File "/home/***/.local/lib/python3.9/site-packages/***/providers/celery/executors/celery_executor_utils.py", line 168, in _execute_in_fork
    args.func(args)
[2024-06-28T23:01:23.949+0000] {logging_mixin.py:188} WARNING -   File "/home/***/.local/lib/python3.9/site-packages/***/cli/cli_config.py", line 49, in command
    return func(*args, **kwargs)
[2024-06-28T23:01:23.950+0000] {logging_mixin.py:188} WARNING -   File "/home/***/.local/lib/python3.9/site-packages/***/utils/cli.py", line 114, in wrapper
    return f(*args, **kwargs)
[2024-06-28T23:01:23.950+0000] {logging_mixin.py:188} WARNING -   File "/home/***/.local/lib/python3.9/site-packages/***/cli/commands/task_command.py", line 441, in task_run
    task_return_code = _run_task_by_selected_method(args, _dag, ti)
[2024-06-28T23:01:23.950+0000] {logging_mixin.py:188} WARNING -   File "/home/***/.local/lib/python3.9/site-packages/***/cli/commands/task_command.py", line 219, in _run_task_by_selected_method
    return _run_task_by_local_task_job(args, ti)
[2024-06-28T23:01:23.950+0000] {logging_mixin.py:188} WARNING -   File "/home/***/.local/lib/python3.9/site-packages/***/cli/commands/task_command.py", line 281, in _run_task_by_local_task_job
    ret = run_job(job=job_runner.job, execute_callable=job_runner._execute)
[2024-06-28T23:01:23.950+0000] {logging_mixin.py:188} WARNING -   File "/home/***/.local/lib/python3.9/site-packages/***/utils/session.py", line 79, in wrapper
    return func(*args, session=session, **kwargs)
[2024-06-28T23:01:23.950+0000] {logging_mixin.py:188} WARNING -   File "/home/***/.local/lib/python3.9/site-packages/***/jobs/job.py", line 402, in run_job
    return execute_job(job, execute_callable=execute_callable)
[2024-06-28T23:01:23.950+0000] {logging_mixin.py:188} WARNING -   File "/home/***/.local/lib/python3.9/site-packages/***/jobs/job.py", line 431, in execute_job
    ret = execute_callable()
[2024-06-28T23:01:23.951+0000] {logging_mixin.py:188} WARNING -   File "/home/***/.local/lib/python3.9/site-packages/***/jobs/local_task_job_runner.py", line 168, in _execute
    self.task_runner.start()
[2024-06-28T23:01:23.951+0000] {logging_mixin.py:188} WARNING -   File "/home/***/.local/lib/python3.9/site-packages/***/task/task_runner/standard_task_runner.py", line 51, in start
    self.process = self._start_by_fork()
[2024-06-28T23:01:23.951+0000] {logging_mixin.py:188} WARNING -   File "/home/***/.local/lib/python3.9/site-packages/***/task/task_runner/standard_task_runner.py", line 103, in _start_by_fork
    ret = args.func(args, dag=self.dag)
[2024-06-28T23:01:23.951+0000] {logging_mixin.py:188} WARNING -   File "/home/***/.local/lib/python3.9/site-packages/***/cli/cli_config.py", line 49, in command
    return func(*args, **kwargs)
[2024-06-28T23:01:23.951+0000] {logging_mixin.py:188} WARNING -   File "/home/***/.local/lib/python3.9/site-packages/***/utils/cli.py", line 114, in wrapper
    return f(*args, **kwargs)
[2024-06-28T23:01:23.951+0000] {logging_mixin.py:188} WARNING -   File "/home/***/.local/lib/python3.9/site-packages/***/cli/commands/task_command.py", line 441, in task_run
    task_return_code = _run_task_by_selected_method(args, _dag, ti)
[2024-06-28T23:01:23.951+0000] {logging_mixin.py:188} WARNING -   File "/home/***/.local/lib/python3.9/site-packages/***/cli/commands/task_command.py", line 221, in _run_task_by_selected_method
    return _run_raw_task(args, ti)
[2024-06-28T23:01:23.951+0000] {logging_mixin.py:188} WARNING -   File "/home/***/.local/lib/python3.9/site-packages/***/cli/commands/task_command.py", line 300, in _run_raw_task
    return ti._run_raw_task(
[2024-06-28T23:01:23.952+0000] {logging_mixin.py:188} WARNING -   File "/home/***/.local/lib/python3.9/site-packages/***/utils/session.py", line 79, in wrapper
    return func(*args, session=session, **kwargs)
[2024-06-28T23:01:23.952+0000] {logging_mixin.py:188} WARNING -   File "/home/***/.local/lib/python3.9/site-packages/***/models/taskinstance.py", line 2479, in _run_raw_task
    self._execute_task_with_callbacks(context, test_mode, session=session)
[2024-06-28T23:01:23.952+0000] {logging_mixin.py:188} WARNING -   File "/home/***/.local/lib/python3.9/site-packages/***/models/taskinstance.py", line 2676, in _execute_task_with_callbacks
    result = self._execute_task(context, task_orig)
[2024-06-28T23:01:23.952+0000] {logging_mixin.py:188} WARNING -   File "/home/***/.local/lib/python3.9/site-packages/***/models/taskinstance.py", line 2701, in _execute_task
    return _execute_task(self, context, task_orig)
[2024-06-28T23:01:23.952+0000] {logging_mixin.py:188} WARNING -   File "/home/***/.local/lib/python3.9/site-packages/***/models/taskinstance.py", line 465, in _execute_task
    result = _execute_callable(context=context, **execute_callable_kwargs)
[2024-06-28T23:01:23.952+0000] {logging_mixin.py:188} WARNING -   File "/home/***/.local/lib/python3.9/site-packages/***/models/taskinstance.py", line 432, in _execute_callable
    return execute_callable(context=context, **execute_callable_kwargs)
[2024-06-28T23:01:23.953+0000] {logging_mixin.py:188} WARNING -   File "/home/***/.local/lib/python3.9/site-packages/***/models/baseoperator.py", line 400, in wrapper
    return func(self, *args, **kwargs)
[2024-06-28T23:01:23.953+0000] {logging_mixin.py:188} WARNING -   File "/home/***/.local/lib/python3.9/site-packages/***/operators/python.py", line 235, in execute
    return_value = self.execute_callable()
[2024-06-28T23:01:23.953+0000] {logging_mixin.py:188} WARNING -   File "/home/***/.local/lib/python3.9/site-packages/***/operators/python.py", line 252, in execute_callable
    return self.python_callable(*self.op_args, **self.op_kwargs)
[2024-06-28T23:01:23.953+0000] {logging_mixin.py:188} WARNING -   File "/opt/***/dags/NYC_Taxi_pipeline.py", line 41, in database_preparation
    logging.info("Error in database_preparation", E, exc_info=True)
[2024-06-28T23:01:23.953+0000] {logging_mixin.py:188} WARNING -   File "/usr/local/lib/python3.9/logging/__init__.py", line 2097, in info
    root.info(msg, *args, **kwargs)
[2024-06-28T23:01:23.953+0000] {logging_mixin.py:188} WARNING -   File "/usr/local/lib/python3.9/logging/__init__.py", line 1446, in info
    self._log(INFO, msg, args, **kwargs)
[2024-06-28T23:01:23.953+0000] {logging_mixin.py:188} WARNING -   File "/usr/local/lib/python3.9/logging/__init__.py", line 1589, in _log
    self.handle(record)
[2024-06-28T23:01:23.953+0000] {logging_mixin.py:188} WARNING -   File "/usr/local/lib/python3.9/logging/__init__.py", line 1599, in handle
    self.callHandlers(record)
[2024-06-28T23:01:23.953+0000] {logging_mixin.py:188} WARNING -   File "/usr/local/lib/python3.9/logging/__init__.py", line 1661, in callHandlers
    hdlr.handle(record)
[2024-06-28T23:01:23.954+0000] {logging_mixin.py:188} WARNING -   File "/usr/local/lib/python3.9/logging/__init__.py", line 952, in handle
    self.emit(record)
[2024-06-28T23:01:23.954+0000] {logging_mixin.py:188} WARNING -   File "/home/***/.local/lib/python3.9/site-packages/***/utils/log/file_task_handler.py", line 248, in emit
    self.handler.emit(record)
[2024-06-28T23:01:23.954+0000] {logging_mixin.py:188} WARNING - Message: 'Error in database_preparation'
Arguments: (TypeError("execute_query() got an unexpected keyword argument 'params'"),)
[2024-06-28T23:01:23.954+0000] {python.py:237} INFO - Done. Returned value was: None
[2024-06-28T23:01:23.956+0000] {taskinstance.py:441} INFO - ::group::Post task execution logs
[2024-06-28T23:01:23.964+0000] {taskinstance.py:1206} INFO - Marking task as SUCCESS. dag_id=NYC_Taxi_pipeline, task_id=database_preparation, run_id=manual__2024-06-28T23:01:22.097185+00:00, execution_date=20240628T230122, start_date=20240628T230123, end_date=20240628T230123
[2024-06-28T23:01:24.021+0000] {local_task_job_runner.py:240} INFO - Task exited with return code 0
[2024-06-28T23:01:24.050+0000] {taskinstance.py:3498} INFO - 1 downstream tasks scheduled from follow-on schedule check
[2024-06-28T23:01:24.051+0000] {local_task_job_runner.py:222} INFO - ::endgroup::
